<?xml version="1.0" encoding="UTF-8"?>
<pd:ProcessDefinition xmlns:xsl="http://www.w3.org/1999/XSL/Transform" xmlns:ns="http://www.tibco.com/pe/EngineTypes" xmlns:pfx0="http://www.tibco.com/CommonLE2/namespace/Public/Pluggable/GUI/Configuration/Query" xmlns:wsdl="http://schemas.xmlsoap.org/wsdl/" xmlns:wsdlPfx="http://www.tibco.com/CommonLE2/namespace/Administration/GUIServices/ExceptionConfiguration" xmlns:ns5="http://www.tibco.com/CommonLE2/namespace/Public/Pluggable/GUI/Common/DeleteQuery" xmlns:ns12="http://www.tibco.com/CommonLE/namespace/Common" xmlns:ns6="http://www.tibco.com/CommonLE2/Private/Administration/DeleteQuery" xmlns:pfx="http://www.tibco.com/pe/DeployedVarsType" xmlns:pd="http://xmlns.tibco.com/bw/process/2003" xmlns:ns2="http://www.tibco.com/CommonLE2/namespace/Administration/GUIServices/Applications/1175798793750" xmlns:ns1="http://www.tibco.com/pe/GenerateErrorActivity/InputSchema" xmlns:ns4="http://www.tibco.com/CommonLE2/namespace/Public/Common/IDQuery" xmlns:ns3="http://www.tibco.com/CommonLE2/Public/Common" xmlns:pfx4="http://www.tibco.com/CommonLE2/Public/Common/Dummy" xmlns:pfx2="http://www.tibco.com/CommonLE2/namespace/private/Common">
    <wsdl:import namespace="http://www.tibco.com/CommonLE2/namespace/Administration/GUIServices/ExceptionConfiguration" location="/SharedResources/WSDL/GUI/Administration/intfRetrieveSpecificExceptionConfigurationList.wsdl"/>
    <pd:name>Administration/GUIServices/ExceptionConfigurationServices/wsDeleteExceptionConfiguration.process</pd:name>
    <pd:startName>Start</pd:startName>
    <pd:startType wsMsgRef="wsdlPfx:DeleteQuery"/>
    <pd:startX>150</pd:startX>
    <pd:startY>50</pd:startY>
    <pd:returnBindings>
        <wsdlPfx:Dummy/>
    </pd:returnBindings>
    <pd:endName>End</pd:endName>
    <pd:endType wsMsgRef="wsdlPfx:Dummy"/>
    <pd:endX>450</pd:endX>
    <pd:endY>50</pd:endY>
    <pd:errorSchemas>
        <Schema1 wsMsgRef="wsdlPfx:Error"/>
    </pd:errorSchemas>
    <pd:processVariables/>
    <pd:targetNamespace>http://xmlns.example.com/1285714937606</pd:targetNamespace>
    <pd:activity name="Call Process">
        <pd:type>com.tibco.pe.core.CallProcessActivity</pd:type>
        <pd:resourceType>ae.process.subprocess</pd:resourceType>
        <pd:x>272</pd:x>
        <pd:y>50</pd:y>
        <config>
            <processName>/Administration/DataAccess/ExceptionConfiguration/Oracle/DeleteExceptionConfiguration.process</processName>
            <processNameXPath>concat('/Administration/DataAccess/ExceptionConfiguration/',$_globalVariables/pfx:GlobalVariables/Database/MIG_DatabaseType,'/DeleteExceptionConfiguration.process')</processNameXPath>
        </config>
        <pd:inputBindings>
            <xsl:for-each select="$Start/wsdlPfx:DeleteQuery/part1/ns5:DeleteQueries">
                <ns6:DeleteQueries>
                    <xsl:for-each select="ns5:Query">
                        <ns6:Query>
                            <ns6:ID>
                                <xsl:value-of select="ns5:ID"/>
                            </ns6:ID>
                            <ns6:AppID>
                                <xsl:value-of select="ns5:AppID"/>
                            </ns6:AppID>
                        </ns6:Query>
                    </xsl:for-each>
                </ns6:DeleteQueries>
            </xsl:for-each>
        </pd:inputBindings>
    </pd:activity>
    <pd:activity name="Catch Exception Config Not Found">
        <pd:type>com.tibco.pe.core.CatchActivity</pd:type>
        <pd:resourceType>ae.activities.catch</pd:resourceType>
        <pd:x>153</pd:x>
        <pd:y>159</pd:y>
        <pd:handler>true</pd:handler>
        <config>
            <fault>localname=DBRecordNotFound namespace=http://www.tibco.com/CommonLE2/namespace/private/Common</fault>
        </config>
        <pd:inputBindings/>
    </pd:activity>
    <pd:activity name="Generate Record Not Found Fault">
        <pd:type>com.tibco.pe.core.GenerateErrorActivity</pd:type>
        <pd:resourceType>ae.activities.throw</pd:resourceType>
        <pd:x>363</pd:x>
        <pd:y>155</pd:y>
        <config>
            <faultName>Schema1</faultName>
        </config>
        <pd:inputBindings>
            <ns1:ActivityInput>
                <message>
                    <xsl:value-of select="$Catch-Exception-Config-Not-Found/pfx2:DBRecordNotFound/pfx2:Message"/>
                </message>
                <xsl:if test="$Catch-Exception-Config-Not-Found/pfx2:DBRecordNotFound/pfx2:Code">
                    <messageCode>
                        <xsl:value-of select="$Catch-Exception-Config-Not-Found/pfx2:DBRecordNotFound/pfx2:Code"/>
                    </messageCode>
                </xsl:if>
                <data>
                    <wsdlPfx:Error>
                        <parameters>
                            <ns3:Error>
                                <ns3:Message>
                                    <xsl:value-of select="$Catch-Exception-Config-Not-Found/pfx2:DBRecordNotFound/pfx2:Message"/>
                                </ns3:Message>
                                <xsl:if test="$Catch-Exception-Config-Not-Found/pfx2:DBRecordNotFound/pfx2:Code">
                                    <ns3:Code>
                                        <xsl:value-of select="$Catch-Exception-Config-Not-Found/pfx2:DBRecordNotFound/pfx2:Code"/>
                                    </ns3:Code>
                                </xsl:if>
                            </ns3:Error>
                        </parameters>
                    </wsdlPfx:Error>
                </data>
            </ns1:ActivityInput>
        </pd:inputBindings>
    </pd:activity>
    <pd:activity name="Catch All">
        <pd:type>com.tibco.pe.core.CatchActivity</pd:type>
        <pd:resourceType>ae.activities.catch</pd:resourceType>
        <pd:x>128</pd:x>
        <pd:y>287</pd:y>
        <pd:handler>true</pd:handler>
        <config>
            <catchAll>true</catchAll>
        </config>
        <pd:inputBindings/>
    </pd:activity>
    <pd:activity name="Generate Internal Error">
        <pd:type>com.tibco.pe.core.GenerateErrorActivity</pd:type>
        <pd:resourceType>ae.activities.throw</pd:resourceType>
        <pd:x>426</pd:x>
        <pd:y>294</pd:y>
        <config>
            <faultName>Schema1</faultName>
        </config>
        <pd:inputBindings>
            <ns1:ActivityInput>
                <xsl:if test="$_error/ns:ErrorReport/Msg">
                    <message>
                        <xsl:value-of select="$_error/ns:ErrorReport/Msg"/>
                    </message>
                </xsl:if>
                <xsl:if test="$_error/ns:ErrorReport/MsgCode">
                    <messageCode>
                        <xsl:value-of select="$_error/ns:ErrorReport/MsgCode"/>
                    </messageCode>
                </xsl:if>
                <data>
                    <wsdlPfx:Error>
                        <parameters>
                            <ns3:Error>
                                <xsl:if test="$_error/ns:ErrorReport/Msg">
                                    <ns3:Message>
                                        <xsl:value-of select="$_error/ns:ErrorReport/Msg"/>
                                    </ns3:Message>
                                </xsl:if>
                                <xsl:if test="$_error/ns:ErrorReport/MsgCode">
                                    <ns3:Code>
                                        <xsl:value-of select="$_error/ns:ErrorReport/MsgCode"/>
                                    </ns3:Code>
                                </xsl:if>
                            </ns3:Error>
                        </parameters>
                    </wsdlPfx:Error>
                </data>
            </ns1:ActivityInput>
        </pd:inputBindings>
    </pd:activity>
    <pd:activity name="Local Exception Handler">
        <pd:type>com.tibco.pe.core.CallProcessActivity</pd:type>
        <pd:resourceType>ae.process.subprocess</pd:resourceType>
        <pd:x>279</pd:x>
        <pd:y>285</pd:y>
        <config>
            <processName>/Common/Local Exception Handler.process</processName>
        </config>
        <pd:inputBindings>
            <ns12:Exception>
                <ErrorMessage>
                    <xsl:value-of select="$_error/ns:ErrorReport/Msg"/>
                </ErrorMessage>
                <ErrorCode>
                    <xsl:value-of select="$_error/ns:ErrorReport/MsgCode"/>
                </ErrorCode>
                <ns12:Error>
                    <xsl:for-each xmlns:xsl="http://www.w3.org/1999/XSL/Transform" select="$_error/ns:ErrorReport">
                        <ns12:ErrorReport>
                            <StackTrace>
                                <xsl:value-of select="StackTrace"/>
                            </StackTrace>
                            <Msg>
                                <xsl:value-of select="Msg"/>
                            </Msg>
                            <FullClass>
                                <xsl:value-of select="FullClass"/>
                            </FullClass>
                            <Class>
                                <xsl:value-of select="Class"/>
                            </Class>
                            <ProcessStack>
                                <xsl:value-of select="ProcessStack"/>
                            </ProcessStack>
                            <MsgCode>
                                <xsl:value-of select="MsgCode"/>
                            </MsgCode>
                        </ns12:ErrorReport>
                    </xsl:for-each>
                </ns12:Error>
            </ns12:Exception>
        </pd:inputBindings>
    </pd:activity>
    <pd:activity name="Catch ReferencedID">
        <pd:type>com.tibco.pe.core.CatchActivity</pd:type>
        <pd:resourceType>ae.activities.catch</pd:resourceType>
        <pd:x>127</pd:x>
        <pd:y>402</pd:y>
        <pd:handler>true</pd:handler>
        <config>
            <fault>localname=ReferencialIntegrityViolation namespace=http://www.tibco.com/CommonLE2/namespace/private/Common</fault>
        </config>
        <pd:inputBindings/>
    </pd:activity>
    <pd:activity name="GenerateReferencedRecordFault">
        <pd:type>com.tibco.pe.core.GenerateErrorActivity</pd:type>
        <pd:resourceType>ae.activities.throw</pd:resourceType>
        <pd:x>368</pd:x>
        <pd:y>396</pd:y>
        <config>
            <faultName>Schema1</faultName>
        </config>
        <pd:inputBindings>
            <ns1:ActivityInput>
                <message>
                    <xsl:value-of select="$Catch-ReferencedID/pfx2:ReferencialIntegrityViolation/pfx2:Message"/>
                </message>
                <messageCode>
                    <xsl:value-of select="$Catch-ReferencedID/pfx2:ReferencialIntegrityViolation/pfx2:Code"/>
                </messageCode>
                <data>
                    <wsdlPfx:Error>
                        <parameters>
                            <ns3:Error>
                                <ns3:Message>
                                    <xsl:value-of select="$Catch-ReferencedID/pfx2:ReferencialIntegrityViolation/pfx2:Message"/>
                                </ns3:Message>
                                <ns3:Code>
                                    <xsl:value-of select="$Catch-ReferencedID/pfx2:ReferencialIntegrityViolation/pfx2:Code"/>
                                </ns3:Code>
                            </ns3:Error>
                        </parameters>
                    </wsdlPfx:Error>
                </data>
            </ns1:ActivityInput>
        </pd:inputBindings>
    </pd:activity>
    <pd:transition>
        <pd:from>Start</pd:from>
        <pd:to>Call Process</pd:to>
        <pd:lineType>Default</pd:lineType>
        <pd:lineColor>-16777216</pd:lineColor>
        <pd:conditionType>always</pd:conditionType>
    </pd:transition>
    <pd:transition>
        <pd:from>Call Process</pd:from>
        <pd:to>End</pd:to>
        <pd:lineType>Default</pd:lineType>
        <pd:lineColor>-16777216</pd:lineColor>
        <pd:conditionType>always</pd:conditionType>
    </pd:transition>
    <pd:transition>
        <pd:from>Catch Exception Config Not Found</pd:from>
        <pd:to>Generate Record Not Found Fault</pd:to>
        <pd:lineType>Default</pd:lineType>
        <pd:lineColor>-16777216</pd:lineColor>
        <pd:conditionType>always</pd:conditionType>
    </pd:transition>
    <pd:transition>
        <pd:from>Catch All</pd:from>
        <pd:to>Local Exception Handler</pd:to>
        <pd:lineType>Default</pd:lineType>
        <pd:lineColor>-16777216</pd:lineColor>
        <pd:conditionType>always</pd:conditionType>
    </pd:transition>
    <pd:transition>
        <pd:from>Local Exception Handler</pd:from>
        <pd:to>Generate Internal Error</pd:to>
        <pd:lineType>Default</pd:lineType>
        <pd:lineColor>-16777216</pd:lineColor>
        <pd:conditionType>always</pd:conditionType>
    </pd:transition>
    <pd:transition>
        <pd:from>Catch ReferencedID</pd:from>
        <pd:to>GenerateReferencedRecordFault</pd:to>
        <pd:lineType>Default</pd:lineType>
        <pd:lineColor>-16777216</pd:lineColor>
        <pd:conditionType>always</pd:conditionType>
    </pd:transition>
</pd:ProcessDefinition>